[2024-03-30 17:25:45,724: WARNING/MainProcess] No hostname was supplied. Reverting to default 'localhost'
[2024-03-30 17:25:46,617: WARNING/MainProcess] /usr/local/lib/python3.12/site-packages/celery/worker/consumer/consumer.py:507: CPendingDeprecationWarning: The broker_connection_retry configuration setting will no longer determine
whether broker connection retries are made during startup in Celery 6.0 and above.
If you wish to retain the existing behavior for retrying connections on startup,
you should set broker_connection_retry_on_startup to True.
  warnings.warn(

[2024-03-30 17:25:46,619: ERROR/MainProcess] consumer: Cannot connect to amqp://guest:**@127.0.0.1:5672//: [Errno 111] Connection refused.
Trying again in 2.00 seconds... (1/100)

[2024-03-30 17:25:48,620: ERROR/MainProcess] consumer: Cannot connect to amqp://guest:**@127.0.0.1:5672//: [Errno 111] Connection refused.
Trying again in 4.00 seconds... (2/100)

[2024-03-30 17:25:52,621: ERROR/MainProcess] consumer: Cannot connect to amqp://guest:**@127.0.0.1:5672//: [Errno 111] Connection refused.
Trying again in 6.00 seconds... (3/100)

[2024-03-30 17:25:58,622: ERROR/MainProcess] consumer: Cannot connect to amqp://guest:**@127.0.0.1:5672//: [Errno 111] Connection refused.
Trying again in 8.00 seconds... (4/100)

[2024-03-30 17:26:06,623: ERROR/MainProcess] consumer: Cannot connect to amqp://guest:**@127.0.0.1:5672//: [Errno 111] Connection refused.
Trying again in 10.00 seconds... (5/100)

[2024-03-30 17:26:16,624: ERROR/MainProcess] consumer: Cannot connect to amqp://guest:**@127.0.0.1:5672//: [Errno 111] Connection refused.
Trying again in 12.00 seconds... (6/100)

[2024-03-30 17:26:28,625: ERROR/MainProcess] consumer: Cannot connect to amqp://guest:**@127.0.0.1:5672//: [Errno 111] Connection refused.
Trying again in 14.00 seconds... (7/100)

[2024-03-30 17:26:42,627: ERROR/MainProcess] consumer: Cannot connect to amqp://guest:**@127.0.0.1:5672//: [Errno 111] Connection refused.
Trying again in 16.00 seconds... (8/100)

[2024-03-30 17:26:58,628: ERROR/MainProcess] consumer: Cannot connect to amqp://guest:**@127.0.0.1:5672//: [Errno 111] Connection refused.
Trying again in 18.00 seconds... (9/100)

[2024-03-30 17:27:16,630: ERROR/MainProcess] consumer: Cannot connect to amqp://guest:**@127.0.0.1:5672//: [Errno 111] Connection refused.
Trying again in 20.00 seconds... (10/100)

[2024-03-30 17:27:36,632: ERROR/MainProcess] consumer: Cannot connect to amqp://guest:**@127.0.0.1:5672//: [Errno 111] Connection refused.
Trying again in 22.00 seconds... (11/100)

[2024-03-30 17:27:58,634: ERROR/MainProcess] consumer: Cannot connect to amqp://guest:**@127.0.0.1:5672//: [Errno 111] Connection refused.
Trying again in 24.00 seconds... (12/100)

[2024-03-30 17:28:22,636: ERROR/MainProcess] consumer: Cannot connect to amqp://guest:**@127.0.0.1:5672//: [Errno 111] Connection refused.
Trying again in 26.00 seconds... (13/100)

[2024-03-30 17:28:48,639: ERROR/MainProcess] consumer: Cannot connect to amqp://guest:**@127.0.0.1:5672//: [Errno 111] Connection refused.
Trying again in 28.00 seconds... (14/100)

[2024-03-30 17:29:16,641: ERROR/MainProcess] consumer: Cannot connect to amqp://guest:**@127.0.0.1:5672//: [Errno 111] Connection refused.
Trying again in 30.00 seconds... (15/100)

[2024-03-30 17:29:41,803: WARNING/MainProcess] No hostname was supplied. Reverting to default 'localhost'
[2024-03-30 17:29:42,684: WARNING/MainProcess] /usr/local/lib/python3.12/site-packages/celery/worker/consumer/consumer.py:507: CPendingDeprecationWarning: The broker_connection_retry configuration setting will no longer determine
whether broker connection retries are made during startup in Celery 6.0 and above.
If you wish to retain the existing behavior for retrying connections on startup,
you should set broker_connection_retry_on_startup to True.
  warnings.warn(

[2024-03-30 17:29:42,686: ERROR/MainProcess] consumer: Cannot connect to amqp://guest:**@127.0.0.1:5672//: [Errno 111] Connection refused.
Trying again in 2.00 seconds... (1/100)

[2024-03-30 17:29:44,687: ERROR/MainProcess] consumer: Cannot connect to amqp://guest:**@127.0.0.1:5672//: [Errno 111] Connection refused.
Trying again in 4.00 seconds... (2/100)

[2024-03-30 17:29:48,688: ERROR/MainProcess] consumer: Cannot connect to amqp://guest:**@127.0.0.1:5672//: [Errno 111] Connection refused.
Trying again in 6.00 seconds... (3/100)

[2024-03-30 17:29:54,689: ERROR/MainProcess] consumer: Cannot connect to amqp://guest:**@127.0.0.1:5672//: [Errno 111] Connection refused.
Trying again in 8.00 seconds... (4/100)

[2024-03-30 17:30:02,690: ERROR/MainProcess] consumer: Cannot connect to amqp://guest:**@127.0.0.1:5672//: [Errno 111] Connection refused.
Trying again in 10.00 seconds... (5/100)

[2024-03-30 17:30:12,691: ERROR/MainProcess] consumer: Cannot connect to amqp://guest:**@127.0.0.1:5672//: [Errno 111] Connection refused.
Trying again in 12.00 seconds... (6/100)

[2024-03-30 17:30:24,692: ERROR/MainProcess] consumer: Cannot connect to amqp://guest:**@127.0.0.1:5672//: [Errno 111] Connection refused.
Trying again in 14.00 seconds... (7/100)

[2024-03-30 17:30:38,694: ERROR/MainProcess] consumer: Cannot connect to amqp://guest:**@127.0.0.1:5672//: [Errno 111] Connection refused.
Trying again in 16.00 seconds... (8/100)

[2024-03-30 17:30:54,696: ERROR/MainProcess] consumer: Cannot connect to amqp://guest:**@127.0.0.1:5672//: [Errno 111] Connection refused.
Trying again in 18.00 seconds... (9/100)

[2024-03-30 17:31:12,698: ERROR/MainProcess] consumer: Cannot connect to amqp://guest:**@127.0.0.1:5672//: [Errno 111] Connection refused.
Trying again in 20.00 seconds... (10/100)

[2024-03-30 17:31:32,700: ERROR/MainProcess] consumer: Cannot connect to amqp://guest:**@127.0.0.1:5672//: [Errno 111] Connection refused.
Trying again in 22.00 seconds... (11/100)

[2024-03-30 17:31:54,702: ERROR/MainProcess] consumer: Cannot connect to amqp://guest:**@127.0.0.1:5672//: [Errno 111] Connection refused.
Trying again in 24.00 seconds... (12/100)

[2024-03-30 17:32:18,705: ERROR/MainProcess] consumer: Cannot connect to amqp://guest:**@127.0.0.1:5672//: [Errno 111] Connection refused.
Trying again in 26.00 seconds... (13/100)

[2024-03-30 17:32:44,707: ERROR/MainProcess] consumer: Cannot connect to amqp://guest:**@127.0.0.1:5672//: [Errno 111] Connection refused.
Trying again in 28.00 seconds... (14/100)

[2024-03-30 17:33:12,710: ERROR/MainProcess] consumer: Cannot connect to amqp://guest:**@127.0.0.1:5672//: [Errno 111] Connection refused.
Trying again in 30.00 seconds... (15/100)

[2024-03-30 17:33:42,713: ERROR/MainProcess] consumer: Cannot connect to amqp://guest:**@127.0.0.1:5672//: [Errno 111] Connection refused.
Trying again in 32.00 seconds... (16/100)

[2024-03-30 17:34:14,717: ERROR/MainProcess] consumer: Cannot connect to amqp://guest:**@127.0.0.1:5672//: [Errno 111] Connection refused.
Trying again in 32.00 seconds... (16/100)

[2024-03-30 17:35:16,614: WARNING/MainProcess] /usr/local/lib/python3.12/site-packages/celery/worker/consumer/consumer.py:507: CPendingDeprecationWarning: The broker_connection_retry configuration setting will no longer determine
whether broker connection retries are made during startup in Celery 6.0 and above.
If you wish to retain the existing behavior for retrying connections on startup,
you should set broker_connection_retry_on_startup to True.
  warnings.warn(

[2024-03-30 17:35:16,619: INFO/MainProcess] Connected to redis://redis:6379/0
[2024-03-30 17:35:16,619: WARNING/MainProcess] /usr/local/lib/python3.12/site-packages/celery/worker/consumer/consumer.py:507: CPendingDeprecationWarning: The broker_connection_retry configuration setting will no longer determine
whether broker connection retries are made during startup in Celery 6.0 and above.
If you wish to retain the existing behavior for retrying connections on startup,
you should set broker_connection_retry_on_startup to True.
  warnings.warn(

[2024-03-30 17:35:16,620: INFO/MainProcess] mingle: searching for neighbors
[2024-03-30 17:35:17,625: INFO/MainProcess] mingle: all alone
[2024-03-30 17:35:17,632: INFO/MainProcess] celery@f11a6185e3d1 ready.
[2024-03-30 17:39:26,312: WARNING/MainProcess] /usr/local/lib/python3.12/site-packages/celery/worker/consumer/consumer.py:507: CPendingDeprecationWarning: The broker_connection_retry configuration setting will no longer determine
whether broker connection retries are made during startup in Celery 6.0 and above.
If you wish to retain the existing behavior for retrying connections on startup,
you should set broker_connection_retry_on_startup to True.
  warnings.warn(

[2024-03-30 17:39:26,317: INFO/MainProcess] Connected to redis://redis:6379/0
[2024-03-30 17:39:26,317: WARNING/MainProcess] /usr/local/lib/python3.12/site-packages/celery/worker/consumer/consumer.py:507: CPendingDeprecationWarning: The broker_connection_retry configuration setting will no longer determine
whether broker connection retries are made during startup in Celery 6.0 and above.
If you wish to retain the existing behavior for retrying connections on startup,
you should set broker_connection_retry_on_startup to True.
  warnings.warn(

[2024-03-30 17:39:26,319: INFO/MainProcess] mingle: searching for neighbors
[2024-03-30 17:39:27,324: INFO/MainProcess] mingle: all alone
[2024-03-30 17:39:27,330: INFO/MainProcess] celery@b336e3b6658a ready.
[2024-03-30 17:43:25,031: WARNING/MainProcess] /usr/local/lib/python3.12/site-packages/celery/worker/consumer/consumer.py:507: CPendingDeprecationWarning: The broker_connection_retry configuration setting will no longer determine
whether broker connection retries are made during startup in Celery 6.0 and above.
If you wish to retain the existing behavior for retrying connections on startup,
you should set broker_connection_retry_on_startup to True.
  warnings.warn(

[2024-03-30 17:43:25,036: INFO/MainProcess] Connected to redis://redis:6379/0
[2024-03-30 17:43:25,036: WARNING/MainProcess] /usr/local/lib/python3.12/site-packages/celery/worker/consumer/consumer.py:507: CPendingDeprecationWarning: The broker_connection_retry configuration setting will no longer determine
whether broker connection retries are made during startup in Celery 6.0 and above.
If you wish to retain the existing behavior for retrying connections on startup,
you should set broker_connection_retry_on_startup to True.
  warnings.warn(

[2024-03-30 17:43:25,037: INFO/MainProcess] mingle: searching for neighbors
[2024-03-30 17:43:26,042: INFO/MainProcess] mingle: all alone
[2024-03-30 17:43:26,049: INFO/MainProcess] celery@fc31c458c445 ready.
